<!--URDF generated by ONSHAPE BY PTC INC, 1.212-->
<robot name="assembly_1">
    <link name="arm1">
        <inertial>
            <mass value="2.23009e-06" />
            <origin xyz="3.29003e-12 -0.0068787 -0.0228539" rpy="0 -0 0" />
            <inertia ixx="5.97231e-10" ixy="0" ixz="0" iyy="6.05003e-10" iyz="-9.5799e-12" izz="1.94128e-11" />
        </inertial>
        <visual>
            <origin xyz="0.0211943 -0.0152254 -0.065" rpy="0 -0 0" />
            <geometry>
                <mesh filename="package://assembly_1/meshes/77.stl" scale="1 1 1" />
            </geometry>
            <material name="0.662745_0.545098_0.462745_0.000000_0.000000">
                <texture />
                <color rgba="0.662745 0.545098 0.462745 1" />
            </material>
        </visual>
    </link>
    <link name="arm1_1">
        <inertial>
            <mass value="2.23009e-06" />
            <origin xyz="3.29001e-12 0.00315733 0.0271461" rpy="0 -0 0" />
            <inertia ixx="5.97231e-10" ixy="0" ixz="0" iyy="6.05003e-10" iyz="-9.5799e-12" izz="1.94128e-11" />
        </inertial>
        <visual>
            <origin xyz="0.0211943 -0.00518933 -0.015" rpy="0 -0 0" />
            <geometry>
                <mesh filename="package://assembly_1/meshes/77.stl" scale="1 1 1" />
            </geometry>
            <material name="0.662745_0.545098_0.462745_0.000000_0.000000">
                <texture />
                <color rgba="0.662745 0.545098 0.462745 1" />
            </material>
        </visual>
    </link>
    <link name="arm1_2">
        <inertial>
            <mass value="2.23009e-06" />
            <origin xyz="3.29001e-12 0.00315733 0.0271461" rpy="0 -0 0" />
            <inertia ixx="5.97231e-10" ixy="0" ixz="0" iyy="6.05003e-10" iyz="-9.5799e-12" izz="1.94128e-11" />
        </inertial>
        <visual>
            <origin xyz="0.0211943 -0.00518933 -0.015" rpy="0 -0 0" />
            <geometry>
                <mesh filename="package://assembly_1/meshes/77.stl" scale="1 1 1" />
            </geometry>
            <material name="0.662745_0.545098_0.462745_0.000000_0.000000">
                <texture />
                <color rgba="0.662745 0.545098 0.462745 1" />
            </material>
        </visual>
    </link>
    <link name="arm1_3">
        <inertial>
            <mass value="2.23009e-06" />
            <origin xyz="3.29001e-12 0.00315733 0.0271461" rpy="0 -0 0" />
            <inertia ixx="5.97231e-10" ixy="0" ixz="0" iyy="6.05003e-10" iyz="-9.5799e-12" izz="1.94128e-11" />
        </inertial>
        <visual>
            <origin xyz="0.0211943 -0.00518933 -0.015" rpy="0 -0 0" />
            <geometry>
                <mesh filename="package://assembly_1/meshes/77.stl" scale="1 1 1" />
            </geometry>
            <material name="0.662745_0.545098_0.462745_0.000000_0.000000">
                <texture />
                <color rgba="0.662745 0.545098 0.462745 1" />
            </material>
        </visual>
    </link>
    <link name="arm2">
        <inertial>
            <mass value="2.45916e-06" />
            <origin xyz="0.0223495 -0.00350176 -0.0187535" rpy="0 -0 0" />
            <inertia ixx="3.03813e-10" ixy="2.0019e-11" ixz="3.33126e-10" iyy="7.07171e-10" iyz="-1.6798e-11" izz="4.21291e-10" />
        </inertial>
        <visual>
            <origin xyz="0.0411943 -0.00276138 -0.065" rpy="0 -0 0" />
            <geometry>
                <mesh filename="package://assembly_1/meshes/67.stl" scale="1 1 1" />
            </geometry>
            <material name="0.662745_0.545098_0.462745_0.000000_0.000000">
                <texture />
                <color rgba="0.662745 0.545098 0.462745 1" />
            </material>
        </visual>
    </link>
    <link name="arm2_1">
        <inertial>
            <mass value="2.45916e-06" />
            <origin xyz="0.0223495 -0.00350176 -0.0187535" rpy="0 -0 0" />
            <inertia ixx="3.03813e-10" ixy="2.0019e-11" ixz="3.33126e-10" iyy="7.07171e-10" iyz="-1.6798e-11" izz="4.21291e-10" />
        </inertial>
        <visual>
            <origin xyz="0.0411943 -0.00276138 -0.065" rpy="0 -0 0" />
            <geometry>
                <mesh filename="package://assembly_1/meshes/67.stl" scale="1 1 1" />
            </geometry>
            <material name="0.662745_0.545098_0.462745_0.000000_0.000000">
                <texture />
                <color rgba="0.662745 0.545098 0.462745 1" />
            </material>
        </visual>
    </link>
    <link name="arm2_2">
        <inertial>
            <mass value="2.45916e-06" />
            <origin xyz="0.0223495 -0.00350176 -0.0187535" rpy="0 -0 0" />
            <inertia ixx="3.03813e-10" ixy="2.0019e-11" ixz="3.33126e-10" iyy="7.07171e-10" iyz="-1.6798e-11" izz="4.21291e-10" />
        </inertial>
        <visual>
            <origin xyz="0.0411943 -0.00276138 -0.065" rpy="0 -0 0" />
            <geometry>
                <mesh filename="package://assembly_1/meshes/67.stl" scale="1 1 1" />
            </geometry>
            <material name="0.662745_0.545098_0.462745_0.000000_0.000000">
                <texture />
                <color rgba="0.662745 0.545098 0.462745 1" />
            </material>
        </visual>
    </link>
    <link name="arm2_3">
        <inertial>
            <mass value="2.45916e-06" />
            <origin xyz="-0.0188448 -0.000740381 0.0462465" rpy="0 -0 0" />
            <inertia ixx="3.03813e-10" ixy="2.0019e-11" ixz="3.33126e-10" iyy="7.07171e-10" iyz="-1.6798e-11" izz="4.21291e-10" />
        </inertial>
        <visual>
            <origin xyz="0 0 0" rpy="0 -0 0" />
            <geometry>
                <mesh filename="package://assembly_1/meshes/67.stl" scale="1 1 1" />
            </geometry>
            <material name="0.662745_0.545098_0.462745_0.000000_0.000000">
                <texture />
                <color rgba="0.662745 0.545098 0.462745 1" />
            </material>
        </visual>
    </link>
    <link name="base arm">
        <inertial>
            <mass value="1.01447e-06" />
            <origin xyz="6.93889e-18 0.00582144 -0.00653226" rpy="0 -0 0" />
            <inertia ixx="3.84841e-11" ixy="0" ixz="0" iyy="3.85039e-11" iyz="-1.69355e-12" izz="1.14135e-11" />
        </inertial>
        <visual>
            <origin xyz="0.0411943 0.00727465 -0.015" rpy="0 -0 0" />
            <geometry>
                <mesh filename="package://assembly_1/meshes/63.stl" scale="1 1 1" />
            </geometry>
            <material name="1.000000_0.772549_0.439216_0.000000_0.000000">
                <texture />
                <color rgba="1 0.772549 0.439216 1" />
            </material>
        </visual>
    </link>
    <link name="base arm_1">
        <inertial>
            <mass value="1.01447e-06" />
            <origin xyz="6.93889e-18 0.000821445 0.00846774" rpy="0 -0 0" />
            <inertia ixx="3.84841e-11" ixy="0" ixz="0" iyy="3.85039e-11" iyz="-1.69355e-12" izz="1.14135e-11" />
        </inertial>
        <visual>
            <origin xyz="0.0411943 0.00227465 0" rpy="0 -0 0" />
            <geometry>
                <mesh filename="package://assembly_1/meshes/63.stl" scale="1 1 1" />
            </geometry>
            <material name="1.000000_0.772549_0.439216_0.000000_0.000000">
                <texture />
                <color rgba="1 0.772549 0.439216 1" />
            </material>
        </visual>
    </link>
    <link name="base arm_2">
        <inertial>
            <mass value="1.01447e-06" />
            <origin xyz="6.93889e-18 0.000821445 0.00846774" rpy="0 -0 0" />
            <inertia ixx="3.84841e-11" ixy="0" ixz="0" iyy="3.85039e-11" iyz="-1.69355e-12" izz="1.14135e-11" />
        </inertial>
        <visual>
            <origin xyz="0.0411943 0.00227465 0" rpy="0 -0 0" />
            <geometry>
                <mesh filename="package://assembly_1/meshes/63.stl" scale="1 1 1" />
            </geometry>
            <material name="1.000000_0.772549_0.439216_0.000000_0.000000">
                <texture />
                <color rgba="1 0.772549 0.439216 1" />
            </material>
        </visual>
    </link>
    <link name="base arm_3">
        <inertial>
            <mass value="1.01447e-06" />
            <origin xyz="6.93889e-18 0.000821445 0.00846774" rpy="0 -0 0" />
            <inertia ixx="3.84841e-11" ixy="0" ixz="0" iyy="3.85039e-11" iyz="-1.69355e-12" izz="1.14135e-11" />
        </inertial>
        <visual>
            <origin xyz="0.0411943 0.00227465 0" rpy="0 -0 0" />
            <geometry>
                <mesh filename="package://assembly_1/meshes/63.stl" scale="1 1 1" />
            </geometry>
            <material name="1.000000_0.772549_0.439216_0.000000_0.000000">
                <texture />
                <color rgba="1 0.772549 0.439216 1" />
            </material>
        </visual>
    </link>
    <link name="body">
        <inertial>
            <mass value="1.59215e-05" />
            <origin xyz="-0.015 -0.0225 0.00010792" rpy="0 -0 0" />
            <inertia ixx="4.88946e-09" ixy="0" ixz="0" iyy="2.98176e-09" iyz="0" izz="7.7932e-09" />
        </inertial>
        <visual>
            <origin xyz="0.00529154 -0.0225 -0.0025" rpy="0 -0 0" />
            <geometry>
                <mesh filename="package://assembly_1/meshes/59.stl" scale="1 1 1" />
            </geometry>
            <material name="0.952941_0.894118_0.788235_0.000000_0.000000">
                <texture />
                <color rgba="0.952941 0.894118 0.788235 1" />
            </material>
        </visual>
    </link>
    <link name="root" />
    <joint name="Revolute 1_0" type="continuous">
        <origin xyz="-2.77556e-17 -0.045 0" rpy="-2.11758e-22 -8.47033e-22 2.47409e-22" />
        <axis xyz="0 0 -1" />
        <parent link="body" />
        <child link="base arm_2" />
    </joint>
    <joint name="Revolute 2 (1)_0" type="continuous">
        <origin xyz="0 -0.005 0.015" rpy="1.05879e-22 -8.47033e-22 1.22465e-16" />
        <axis xyz="1.22465e-16 1 1.27465e-32" />
        <parent link="base arm_3" />
        <child link="arm1_1" />
    </joint>
    <joint name="Revolute 2 (2)_0" type="continuous">
        <origin xyz="2.77556e-17 -0.005 0.015" rpy="1.05879e-22 -8.47033e-22 1.22465e-16" />
        <axis xyz="1.22465e-16 1 1.27465e-32" />
        <parent link="base arm_1" />
        <child link="arm1_2" />
    </joint>
    <joint name="Revolute 2 (3)_0" type="continuous">
        <origin xyz="0 -0.010036 -0.05" rpy="-1.05879e-22 1.23259e-32 -1.22465e-16" />
        <axis xyz="0 1 0" />
        <parent link="arm1" />
        <child link="base arm" />
    </joint>
    <joint name="Revolute 2_0" type="continuous">
        <origin xyz="-1.38778e-17 -0.005 0.015" rpy="-2.11758e-22 -8.47033e-22 1.22465e-16" />
        <axis xyz="1.22465e-16 1 1.27465e-32" />
        <parent link="base arm_2" />
        <child link="arm1_3" />
    </joint>
    <joint name="Revolute 3 (1)_0" type="continuous">
        <origin xyz="0 0.010036 0.05" rpy="-1.05879e-22 1.30977e-44 2.47408e-22" />
        <axis xyz="-1.22465e-16 -1 -1.64586e-32" />
        <parent link="arm1_1" />
        <child link="arm2" />
    </joint>
    <joint name="Revolute 3 (2)_0" type="continuous">
        <origin xyz="2.77556e-17 0.010036 0.05" rpy="-1.05879e-22 1.30977e-44 2.47408e-22" />
        <axis xyz="-1.22465e-16 -1 -1.64586e-32" />
        <parent link="arm1_2" />
        <child link="arm2_1" />
    </joint>
    <joint name="Revolute 3 (3)_0" type="continuous">
        <origin xyz="-0.0411943 0.00276138 0.065" rpy="-1.05879e-22 1.30977e-44 2.47408e-22" />
        <axis xyz="-1.22465e-16 -1 -1.27465e-32" />
        <parent link="arm2_3" />
        <child link="arm1" />
    </joint>
    <joint name="Revolute 3_0" type="continuous">
        <origin xyz="-2.77556e-17 0.010036 0.05" rpy="-1.05879e-22 1.30977e-44 2.47408e-22" />
        <axis xyz="-1.22465e-16 -1 -1.64586e-32" />
        <parent link="arm1_3" />
        <child link="arm2_2" />
    </joint>
    <joint name="Revolute 4_0" type="continuous">
        <origin xyz="-0.03 -0.045 0" rpy="-2.11758e-22 -8.47033e-22 2.83059e-22" />
        <axis xyz="0 0 -1" />
        <parent link="body" />
        <child link="base arm_3" />
    </joint>
    <joint name="Revolute 5_0" type="continuous">
        <origin xyz="-0.03 -2.77556e-17 0" rpy="-2.11758e-22 -8.47033e-22 2.83059e-22" />
        <axis xyz="0 0 -1" />
        <parent link="body" />
        <child link="base arm_1" />
    </joint>
    <joint name="Revolute 6_0" type="continuous">
        <origin xyz="2.08167e-16 0.005 -0.015" rpy="1.05879e-22 -8.47033e-22 -1.4046e-22" />
        <axis xyz="0 0 -1" />
        <parent link="base arm" />
        <child link="body" />
    </joint>
    <joint name="hanging_node_to_root_joint_0" type="fixed">
        <origin xyz="-0.0665719 0.0700615 0.0288832" rpy="1.01721e-06 -9.86836e-06 2.28534e-06" />
        <axis xyz="0 0 1" />
        <parent link="root" />
        <child link="arm2_3" />
    </joint>
</robot>
